<?xml version="1.0"?>

<robot name="differential_drive_robot" xmlns:xacro="http://www.ros.org/wiki/xacro">

<!-- Pi constant -->
<xacro:property name="pi_const" value="3.14159265"/>

<!-- Body Dimensions -->
<xacro:property name="a" value="1.0"/>
<xacro:property name="b" value="0.3"/>
<xacro:property name="c" value="0.6"/>

<!-- Wheel & Caster Dimension -->
<xacro:property name="r" value="0.15"/>
<xacro:property name="d" value="0.1"/>


<xacro:property name="s1" value="${b/2+r}"/>
<xacro:property name="s2" value="${2*r}"/>
<xacro:property name="s3" value="${2*r}"/>
<xacro:property name="s4" value="${c/2+d/2}"/>


<!-- Mass & Inertia -->
<!-- Body Material Density -->
<xacro:property name="d1" value="2710.0"/>
<!-- Wheel Material Density -->
<xacro:property name="d2" value="2710.0"/>
<!-- Caster Material Density -->
<xacro:property name="d3" value="2710.0"/>


<!-- Robot Body Mass, Wheel Mass, Caster Mass -->
<!-- Body -->
<xacro:property name="m1" value="${d1*a*b*c}"/>
<!-- Wheel -->
<xacro:property name="m2" value="${d2*pi_const*r*r*d}"/>
<!-- Caster -->
<xacro:property name="m3" value="${d3*(4.0/3.0)*pi_const*r*r*r}"/>


<!-- Moments of Inertia of the robot body -->
<xacro:property name="Ix_body" value="${(1/12)*m1*(b*b+c*c)}"/>
<xacro:property name="Iy_body" value="${(1/12)*m1*(a*a+b*b)}"/>
<xacro:property name="Iz_body" value="${(1/12)*m1*(a*a+c*c)}"/>


<!-- Moments of Inertia of the Wheel -->
<xacro:property name="Iz_wheel" value="${0.5*m2*r*r}"/>
<xacro:property name="I_wheel" value="${(1.0/12.0)*m2*(3.0*r*r+d*d)}"/>


<!-- Moments of Inertia of the Caster Sphere -->
<xacro:property name="I_caster" value="${(2.0/5.0)*m3*r*r}"/>

<xacro:macro name="inertia_body">
	<inertial>
	<origin rpy="0 0 0" xyz="0 0 ${s1}"/>
	<mass value="${m1}"/>
	<inertia ixx="${Ix_body}" ixy="0.0" ixz="0.0" iyy="${Iy_body}" iyz="0.0" izz="${Iz_body}" />
	</inertial>
</xacro:macro>

<xacro:macro name="inertia_wheel">
	<inertial>
	<origin rpy="1.570795 0 0" xyz="0 0 0"/>
	<mass value="${m2}"/>
	<inertia ixx="${I_wheel}" ixy="0.0" ixz="0.0" iyy="${I_wheel}" iyz="0.0" izz="${Iz_wheel}" />
	</inertial>
</xacro:macro>

<xacro:macro name="inertia_caster">
	<inertial>
	<origin rpy="0 0 0" xyz="0 0 0"/>
	<mass value="${m3}"/>
	<inertia ixx="${I_caster}" ixy="0.0" ixz="0.0" iyy="${I_caster}" iyz="0.0" izz="${I_caster}" />
	</inertial>
</xacro:macro>


<!-- Include Additional Files -->
<xacro:include filename="$(find mobile_robot)/model/robot.gazebo" />


<!-- From here we define Links, Joints -->

<!-- START: Fictious link of robot -->
<link name="base_footprint"> </link>
<joint name="body_link_joint" type="fixed">
	<parent link="base_footprint"/>
	<child link="body_link"/>
</joint>
<!-- END: Fictious link of robot -->


<!-- START: Body link of robot -->
<link name="body_link">
	<visual>
		<geometry>
			<box size= "${a} ${c} ${b}" />
		</geometry>
	<origin rpy="0 0 0" xyz="0 0 ${s1}" />
	</visual>

	<collision>
		<geometry>
			<box size= "${a} ${c} ${b}" />
		</geometry>
		<origin rpy="0 0 0" xyz="0 0 ${s1}" />
	</collision>
	<xacro:inertia_body />
</link>
<!-- END: Body link of robot -->


<!-- START: Back Right Wheel of robot & the joint -->
<joint name="wheel1_joint" type="continuous">
	<parent link="body_link" />
	<child link="wheel1_link" />
	<origin xyz="${-s2} ${-s4} ${r}" rpy="0 0 0" />
	<axis xyz= "0 1 0" />
	<limit effort="50000" velocity="10" />
	<dynamic damping="1.0" friction="1.0" />
</joint>

<link name="wheel1_link">
	<visual>
		<origin rpy="1.570795 0 0" xyz="0 0 0" />
		<geometry>
			<cylinder length="${d}" radius="${r}" />
		</geometry>
	</visual>

	<collision>
		<origin rpy="1.570795 0 0" xyz="0 0 0" />
		<geometry>
			<cylinder length="${d}" radius="${r}" />
		</geometry>
	</collision>
	<xacro:inertia_wheel />
</link>
<!-- END: Back Right Wheel of robot & the joint -->


<!-- START: Back Left Wheel of robot & the joint -->
<joint name="wheel2_joint" type="continuous">
	<parent link="body_link" />
	<child link="wheel2_link" />
	<origin xyz="${-s2} ${s4} ${r}" rpy="0 0 0" />
	<axis xyz= "0 1 0" />
	<limit effort="50000" velocity="10" />
	<dynamic damping="1.0" friction="1.0" />
</joint>

<link name="wheel2_link">
	<visual>
		<origin rpy="1.570795 0 0" xyz="0 0 0" />
		<geometry>
			<cylinder length="${d}" radius="${r}" />
		</geometry>
	</visual>

	<collision>
		<origin rpy="1.570795 0 0" xyz="0 0 0" />
		<geometry>
			<cylinder length="${d}" radius="${r}" />
		</geometry>
	</collision>
	<xacro:inertia_wheel />
</link>
<!-- END: Back Left Wheel of robot & the joint -->


<!-- START: Caster wheel -->
<joint name="caster_wheel" type="fixed">
	<parent link="body_link" />
	<child link="caster_link" />
	<origin xyz="${s3} 0 ${r}" rpy="0 0 0" />
</joint>

<link name="caster_link">
	<visual>
		<origin rpy="0 0 0" xyz="0 0 0" />
		<geometry>
			<sphere radius="${r}" />
		</geometry>
	</visual>

	<collision>
		<origin rpy="0 0 0" xyz="0 0 0" />
		<geometry>
			<sphere radius="${r}" />
		</geometry>
	</collision>
	<xacro:inertia_caster />
</link>
<!-- END: Caster wheel -->


<!-- START: Lidar -->
<joint name="lidar_joint" type="fixed">
	<origin xyz="0.0 0 ${b+r}" rpy="0 0 0" />
	<parent link="body_link" />
	<child link="lidar_link" />
	<axis xyz="0 1 0" rpy="0 0 0" />
</joint>

<link name='lidar_link'>
	<visual>
		<origin xyz="0 0 0.05" rpy="0 0 0" />
		<geometry>
			<cylinder length="0.1" radius="0.1" />
		</geometry>
	</visual>

	<collision name='collision'>
		<origin xyz="0 0 0.05" rpy="0 0 0" />
		<geometry>
			<cylinder length="0.1" radius="0.1" />
		</geometry>
	</collision>

	<inertial>
		<mass value="1e-6" />
		<origin xyz="0 0 0" rpy="0 0 0" />
		<inertia ixx="1e-6" ixy="0" ixz="0"
				 iyy="1e-6" iyz="0" izz="1e-6"
		/>
	</inertial>
</link>
<!-- END: Lidar -->


</robot>